Workbook

Sheet Início
B1: 📦 CONTROLE DE MATERIAL — 2026
B2: Sistema de Gestão de Estoque • v4.0
B4: 📋 ESTRUTURA DA PLANILHA
B5: 📊 Dashboard | C5: Visão executiva: KPIs, gráficos e alertas críticos. Atualiza automaticamente.
B6: 📦 Estoque Atual | C6: Saldo em tempo real por material com cálculo de consumo médio, dias até zerar e ponto de reposição.
B7: 📝 Movimentações | C7: Registro de todas as entradas e saídas. Use as listas suspensas para evitar erros.
B8: 👥 Cad. Colaboradores | C8: Cadastro centralizado de quem retira materiais. Adicione ou desative aqui.
B9: 🗂️ Cad. Materiais | C9: Fonte única de verdade dos materiais: unidade, custo, fornecedor, lead time.
B10: ⚙️ Listas (oculta) | C10: Suporte interno para validações. Não editar.
B12: ✏️ COMO USAR
B13: ➕ Registrar movimento | C13: Vá para a aba 'Movimentações' e preencha uma nova linha. As listas suspensas garantem consistência.
B14: 🆕 Adicionar material | C14: Cadastre na aba 'Cad. Materiais' (próxima linha vazia). A planilha reconhece automaticamente em todas as outras abas.
B15: 🆕 Adicionar colaborador | C15: Cadastre na aba 'Cad. Colaboradores'. Aparecerá imediatamente nas listas suspensas.
B16: 🚫 Desativar item | C16: Em vez de apagar, mude a coluna 'Ativo?' para 'Não'. Isso preserva o histórico e remove das listas ativas.
B17: 📈 Ler o Dashboard | C17: KPIs no topo, gráficos no meio, lista de alertas embaixo. Tudo recalcula sozinho.
B18: ⚠️ Alertas de estoque | C18: A coluna Status mostra 4 níveis: Sem Estoque (vermelho), Abaixo do Mín. (amarelo), Estoque Baixo (laranja) e Normal (verde).
B20: 📊 INDICADORES CALCULADOS
B21: Consumo Médio Mensal | C21: Total de saídas dividido pelo número de meses ativos.
B22: Consumo Médio Diário | C22: Saídas totais / dias decorridos no ano. Base para previsão.
B23: Dias até Zerar | C23: Estoque atual ÷ consumo diário. Se ≤ lead time, é hora de comprar.
B24: Ponto de Reposição | C24: (Consumo diário × lead time do fornecedor) + estoque mínimo de segurança.
B25: Valor em Estoque (R$) | C25: Estoque atual × custo unitário. Total no Dashboard.
B26: Última Movimentação | C26: Data do último registro. Material 'parado' há muito tempo merece revisão.
B28: ✅ Compatível com Excel 2016+, Microsoft 365, Google Sheets, LibreOffice • Dúvidas? Entre em contato com a equipe de Compras

Sheet Dashboard
A1: 📊 DASHBOARD — CONTROLE DE MATERIAL 2026
A3: 📦 Materiais Cadastrados | D3: 💰 Valor em Estoque (R$) | G3: ⚠ Sem Estoque | J3: ⬇ Abaixo do Mín. | M3: 📝 Movim. 2026
A4: =COUNTIF('Cad. Materiais'!$B$4:$B$53,"?*") -> 25 | D4: =SUM('Estoque Atual'!$K$4:$K$53) -> 1039.7 | G4: =COUNTIF('Estoque Atual'!$L$4:$L$53,"⚠ SEM ESTOQUE") -> 10 | J4: =COUNTIF('Estoque Atual'!$L$4:$L$53,"⬇ ABAIXO DO MÍN.") -> 1 | M4: =COUNTIF(Movimentações!$A$4:$A$5000,">0") -> 79
A6: 📅 MOVIMENTAÇÕES POR MÊS | F6: 📦 TOP 10 MATERIAIS MAIS CONSUMIDOS | K6: 🚨 ALERTAS DE COMPRA URGENTE
A7: Mês | B7: Entradas | C7: Saídas | D7: Saldo | F7: # | G7: Material | H7: Saídas | I7: Estoque Atual | K7: Material | L7: Atual | M7: Mín. | N7: Status
A8: Janeiro | B8: =IFERROR(SUMIFS(Movimentações!$E$4:$E$5000,Movimentações!$B$4:$B$5000,">="&DATE(2026,1,1),Movimentações!$B$4:$B$5000,"<="&EOMONTH(DATE(2026,1,1),0),Movimentações!$D$4:$D$5000,"Entrada"),0) -> 16 | C8: =IFERROR(SUMIFS(Movimentações!$E$4:$E$5000,Movimentações!$B$4:$B$5000,">="&DATE(2026,1,1),Movimentações!$B$4:$B$5000,"<="&EOMONTH(DATE(2026,1,1),0),Movimentações!$D$4:$D$5000,"Saída"),0) -> 72 | D8: =B8-C8 -> -56 | F8: 1 | G8: =IFERROR(IF(LARGE('Estoque Atual'!$R$4:$R$53,1)<0,"",INDEX('Estoque Atual'!$A$4:$A$53,MATCH(LARGE('Estoque Atual'!$R$4:$R$53,1),'Estoque Atual'!$R$4:$R$53,0))),"") -> Envelope Janelado | H8: =IFERROR(IF(LARGE('Estoque Atual'!$R$4:$R$53,1)<0,"",INDEX('Estoque Atual'!$I$4:$I$53,MATCH(LARGE('Estoque Atual'!$R$4:$R$53,1),'Estoque Atual'!$R$4:$R$53,0))),"") -> 198 | I8: =IFERROR(IF(LARGE('Estoque Atual'!$R$4:$R$53,1)<0,"",INDEX('Estoque Atual'!$J$4:$J$53,MATCH(LARGE('Estoque Atual'!$R$4:$R$53,1),'Estoque Atual'!$R$4:$R$53,0))),"") -> 302 | K8: =IFERROR(IF(SMALL('Estoque Atual'!$Q$4:$Q$53,1)>=999999,"",INDEX('Estoque Atual'!$A$4:$A$53,MATCH(SMALL('Estoque Atual'!$Q$4:$Q$53,1),'Estoque Atual'!$Q$4:$Q$53,0))),"") -> Caneta Vermelha | L8: =IFERROR(IF(SMALL('Estoque Atual'!$Q$4:$Q$53,1)>=999999,"",INDEX('Estoque Atual'!$J$4:$J$53,MATCH(SMALL('Estoque Atual'!$Q$4:$Q$53,1),'Estoque Atual'!$Q$4:$Q$53,0))),"") -> 0 | M8: =IFERROR(IF(SMALL('Estoque Atual'!$Q$4:$Q$53,1)>=999999,"",INDEX('Estoque Atual'!$D$4:$D$53,MATCH(SMALL('Estoque Atual'!$Q$4:$Q$53,1),'Estoque Atual'!$Q$4:$Q$53,0))),"") -> 5 | N8: =IFERROR(IF(SMALL('Estoque Atual'!$Q$4:$Q$53,1)>=999999,"",INDEX('Estoque Atual'!$L$4:$L$53,MATCH(SMALL('Estoque Atual'!$Q$4:$Q$53,1),'Estoque Atual'!$Q$4:$Q$53,0))),"") -> ⚠ SEM ESTOQUE
A9: Fevereiro | B9: =IFERROR(SUMIFS(Movimentações!$E$4:$E$5000,Movimentações!$B$4:$B$5000,">="&DATE(2026,2,1),Movimentações!$B$4:$B$5000,"<="&EOMONTH(DATE(2026,2,1),0),Movimentações!$D$4:$D$5000,"Entrada"),0) -> 213 | C9: =IFERROR(SUMIFS(Movimentações!$E$4:$E$5000,Movimentações!$B$4:$B$5000,">="&DATE(2026,2,1),Movimentações!$B$4:$B$5000,"<="&EOMONTH(DATE(2026,2,1),0),Movimentações!$D$4:$D$5000,"Saída"),0) -> 93 | D9: =B9-C9 -> 120 | F9: 2 | G9: =IFERROR(IF(LARGE('Estoque Atual'!$R$4:$R$53,2)<0,"",INDEX('Estoque Atual'!$A$4:$A$53,MATCH(LARGE('Estoque Atual'!$R$4:$R$53,2),'Estoque Atual'!$R$4:$R$53,0))),"") -> Resma de papel A4 | H9: =IFERROR(IF(LARGE('Estoque Atual'!$R$4:$R$53,2)<0,"",INDEX('Estoque Atual'!$I$4:$I$53,MATCH(LARGE('Estoque Atual'!$R$4:$R$53,2),'Estoque Atual'!$R$4:$R$53,0))),"") -> 56 | I9: =IFERROR(IF(LARGE('Estoque Atual'!$R$4:$R$53,2)<0,"",INDEX('Estoque Atual'!$J$4:$J$53,MATCH(LARGE('Estoque Atual'!$R$4:$R$53,2),'Estoque Atual'!$R$4:$R$53,0))),"") -> 6 | K9: =IFERROR(IF(SMALL('Estoque Atual'!$Q$4:$Q$53,2)>=999999,"",INDEX('Estoque Atual'!$A$4:$A$53,MATCH(SMALL('Estoque Atual'!$Q$4:$Q$53,2),'Estoque Atual'!$Q$4:$Q$53,0))),"") -> Pilhas | L9: =IFERROR(IF(SMALL('Estoque Atual'!$Q$4:$Q$53,2)>=999999,"",INDEX('Estoque Atual'!$J$4:$J$53,MATCH(SMALL('Estoque Atual'!$Q$4:$Q$53,2),'Estoque Atual'!$Q$4:$Q$53,0))),"") -> 0 | M9: =IFERROR(IF(SMALL('Estoque Atual'!$Q$4:$Q$53,2)>=999999,"",INDEX('Estoque Atual'!$D$4:$D$53,MATCH(SMALL('Estoque Atual'!$Q$4:$Q$53,2),'Estoque Atual'!$Q$4:$Q$53,0))),"") -> 4 | N9: =IFERROR(IF(SMALL('Estoque Atual'!$Q$4:$Q$53,2)>=999999,"",INDEX('Estoque Atual'!$L$4:$L$53,MATCH(SMALL('Estoque Atual'!$Q$4:$Q$53,2),'Estoque Atual'!$Q$4:$Q$53,0))),"") -> ⚠ SEM ESTOQUE
A10: Março | B10: =IFERROR(SUMIFS(Movimentações!$E$4:$E$5000,Movimentações!$B$4:$B$5000,">="&DATE(2026,3,1),Movimentações!$B$4:$B$5000,"<="&EOMONTH(DATE(2026,3,1),0),Movimentações!$D$4:$D$5000,"Entrada"),0) -> 78 | C10: =IFERROR(SUMIFS(Movimentações!$E$4:$E$5000,Movimentações!$B$4:$B$5000,">="&DATE(2026,3,1),Movimentações!$B$4:$B$5000,"<="&EOMONTH(DATE(2026,3,1),0),Movimentações!$D$4:$D$5000,"Saída"),0) -> 82 | D10: =B10-C10 -> -4 | F10: 3 | G10: =IFERROR(IF(LARGE('Estoque Atual'!$R$4:$R$53,3)<0,"",INDEX('Estoque Atual'!$A$4:$A$53,MATCH(LARGE('Estoque Atual'!$R$4:$R$53,3),'Estoque Atual'!$R$4:$R$53,0))),"") -> Envelope Pardo | H10: =IFERROR(IF(LARGE('Estoque Atual'!$R$4:$R$53,3)<0,"",INDEX('Estoque Atual'!$I$4:$I$53,MATCH(LARGE('Estoque Atual'!$R$4:$R$53,3),'Estoque Atual'!$R$4:$R$53,0))),"") -> 20 | I10: =IFERROR(IF(LARGE('Estoque Atual'!$R$4:$R$53,3)<0,"",INDEX('Estoque Atual'!$J$4:$J$53,MATCH(LARGE('Estoque Atual'!$R$4:$R$53,3),'Estoque Atual'!$R$4:$R$53,0))),"") -> 185 | K10: =IFERROR(IF(SMALL('Estoque Atual'!$Q$4:$Q$53,3)>=999999,"",INDEX('Estoque Atual'!$A$4:$A$53,MATCH(SMALL('Estoque Atual'!$Q$4:$Q$53,3),'Estoque Atual'!$Q$4:$Q$53,0))),"") -> Post-IT | L10: =IFERROR(IF(SMALL('Estoque Atual'!$Q$4:$Q$53,3)>=999999,"",INDEX('Estoque Atual'!$J$4:$J$53,MATCH(SMALL('Estoque Atual'!$Q$4:$Q$53,3),'Estoque Atual'!$Q$4:$Q$53,0))),"") -> 0 | M10: =IFERROR(IF(SMALL('Estoque Atual'!$Q$4:$Q$53,3)>=999999,"",INDEX('Estoque Atual'!$D$4:$D$53,MATCH(SMALL('Estoque Atual'!$Q$4:$Q$53,3),'Estoque Atual'!$Q$4:$Q$53,0))),"") -> 2 | N10: =IFERROR(IF(SMALL('Estoque Atual'!$Q$4:$Q$53,3)>=999999,"",INDEX('Estoque Atual'!$L$4:$L$53,MATCH(SMALL('Estoque Atual'!$Q$4:$Q$53,3),'Estoque Atual'!$Q$4:$Q$53,0))),"") -> ⚠ SEM ESTOQUE
A11: Abril | B11: =IFERROR(SUMIFS(Movimentações!$E$4:$E$5000,Movimentações!$B$4:$B$5000,">="&DATE(2026,4,1),Movimentações!$B$4:$B$5000,"<="&EOMONTH(DATE(2026,4,1),0),Movimentações!$D$4:$D$5000,"Entrada"),0) -> 15 | C11: =IFERROR(SUMIFS(Movimentações!$E$4:$E$5000,Movimentações!$B$4:$B$5000,">="&DATE(2026,4,1),Movimentações!$B$4:$B$5000,"<="&EOMONTH(DATE(2026,4,1),0),Movimentações!$D$4:$D$5000,"Saída"),0) -> 23 | D11: =B11-C11 -> -8 | F11: 4 | G11: =IFERROR(IF(LARGE('Estoque Atual'!$R$4:$R$53,4)<0,"",INDEX('Estoque Atual'!$A$4:$A$53,MATCH(LARGE('Estoque Atual'!$R$4:$R$53,4),'Estoque Atual'!$R$4:$R$53,0))),"") -> Caneta Azul | H11: =IFERROR(IF(LARGE('Estoque Atual'!$R$4:$R$53,4)<0,"",INDEX('Estoque Atual'!$I$4:$I$53,MATCH(LARGE('Estoque Atual'!$R$4:$R$53,4),'Estoque Atual'!$R$4:$R$53,0))),"") -> 6 | I11: =IFERROR(IF(LARGE('Estoque Atual'!$R$4:$R$53,4)<0,"",INDEX('Estoque Atual'!$J$4:$J$53,MATCH(LARGE('Estoque Atual'!$R$4:$R$53,4),'Estoque Atual'!$R$4:$R$53,0))),"") -> 44 | K11: =IFERROR(IF(SMALL('Estoque Atual'!$Q$4:$Q$53,4)>=999999,"",INDEX('Estoque Atual'!$A$4:$A$53,MATCH(SMALL('Estoque Atual'!$Q$4:$Q$53,4),'Estoque Atual'!$Q$4:$Q$53,0))),"") -> Marcador de texto | L11: =IFERROR(IF(SMALL('Estoque Atual'!$Q$4:$Q$53,4)>=999999,"",INDEX('Estoque Atual'!$J$4:$J$53,MATCH(SMALL('Estoque Atual'!$Q$4:$Q$53,4),'Estoque Atual'!$Q$4:$Q$53,0))),"") -> 0 | M11: =IFERROR(IF(SMALL('Estoque Atual'!$Q$4:$Q$53,4)>=999999,"",INDEX('Estoque Atual'!$D$4:$D$53,MATCH(SMALL('Estoque Atual'!$Q$4:$Q$53,4),'Estoque Atual'!$Q$4:$Q$53,0))),"") -> 2 | N11: =IFERROR(IF(SMALL('Estoque Atual'!$Q$4:$Q$53,4)>=999999,"",INDEX('Estoque Atual'!$L$4:$L$53,MATCH(SMALL('Estoque Atual'!$Q$4:$Q$53,4),'Estoque Atual'!$Q$4:$Q$53,0))),"") -> ⚠ SEM ESTOQUE
A12: Maio | B12: =IFERROR(SUMIFS(Movimentações!$E$4:$E$5000,Movimentações!$B$4:$B$5000,">="&DATE(2026,5,1),Movimentações!$B$4:$B$5000,"<="&EOMONTH(DATE(2026,5,1),0),Movimentações!$D$4:$D$5000,"Entrada"),0) -> 0 | C12: =IFERROR(SUMIFS(Movimentações!$E$4:$E$5000,Movimentações!$B$4:$B$5000,">="&DATE(2026,5,1),Movimentações!$B$4:$B$5000,"<="&EOMONTH(DATE(2026,5,1),0),Movimentações!$D$4:$D$5000,"Saída"),0) -> 20 | D12: =B12-C12 -> -20 | F12: 5 | G12: =IFERROR(IF(LARGE('Estoque Atual'!$R$4:$R$53,5)<0,"",INDEX('Estoque Atual'!$A$4:$A$53,MATCH(LARGE('Estoque Atual'!$R$4:$R$53,5),'Estoque Atual'!$R$4:$R$53,0))),"") -> Elástico | H12: =IFERROR(IF(LARGE('Estoque Atual'!$R$4:$R$53,5)<0,"",INDEX('Estoque Atual'!$I$4:$I$53,MATCH(LARGE('Estoque Atual'!$R$4:$R$53,5),'Estoque Atual'!$R$4:$R$53,0))),"") -> 3 | I12: =IFERROR(IF(LARGE('Estoque Atual'!$R$4:$R$53,5)<0,"",INDEX('Estoque Atual'!$J$4:$J$53,MATCH(LARGE('Estoque Atual'!$R$4:$R$53,5),'Estoque Atual'!$R$4:$R$53,0))),"") -> 9 | K12: =IFERROR(IF(SMALL('Estoque Atual'!$Q$4:$Q$53,5)>=999999,"",INDEX('Estoque Atual'!$A$4:$A$53,MATCH(SMALL('Estoque Atual'!$Q$4:$Q$53,5),'Estoque Atual'!$Q$4:$Q$53,0))),"") -> Durex grande | L12: =IFERROR(IF(SMALL('Estoque Atual'!$Q$4:$Q$53,5)>=999999,"",INDEX('Estoque Atual'!$J$4:$J$53,MATCH(SMALL('Estoque Atual'!$Q$4:$Q$53,5),'Estoque Atual'!$Q$4:$Q$53,0))),"") -> 0 | M12: =IFERROR(IF(SMALL('Estoque Atual'!$Q$4:$Q$53,5)>=999999,"",INDEX('Estoque Atual'!$D$4:$D$53,MATCH(SMALL('Estoque Atual'!$Q$4:$Q$53,5),'Estoque Atual'!$Q$4:$Q$53,0))),"") -> 2 | N12: =IFERROR(IF(SMALL('Estoque Atual'!$Q$4:$Q$53,5)>=999999,"",INDEX('Estoque Atual'!$L$4:$L$53,MATCH(SMALL('Estoque Atual'!$Q$4:$Q$53,5),'Estoque Atual'!$Q$4:$Q$53,0))),"") -> ⚠ SEM ESTOQUE
A13: Junho | B13: =IFERROR(SUMIFS(Movimentações!$E$4:$E$5000,Movimentações!$B$4:$B$5000,">="&DATE(2026,6,1),Movimentações!$B$4:$B$5000,"<="&EOMONTH(DATE(2026,6,1),0),Movimentações!$D$4:$D$5000,"Entrada"),0) -> 0 | C13: =IFERROR(SUMIFS(Movimentações!$E$4:$E$5000,Movimentações!$B$4:$B$5000,">="&DATE(2026,6,1),Movimentações!$B$4:$B$5000,"<="&EOMONTH(DATE(2026,6,1),0),Movimentações!$D$4:$D$5000,"Saída"),0) -> 0 | D13: =B13-C13 -> 0 | F13: 6 | G13: =IFERROR(IF(LARGE('Estoque Atual'!$R$4:$R$53,6)<0,"",INDEX('Estoque Atual'!$A$4:$A$53,MATCH(LARGE('Estoque Atual'!$R$4:$R$53,6),'Estoque Atual'!$R$4:$R$53,0))),"") -> Grampo normal | H13: =IFERROR(IF(LARGE('Estoque Atual'!$R$4:$R$53,6)<0,"",INDEX('Estoque Atual'!$I$4:$I$53,MATCH(LARGE('Estoque Atual'!$R$4:$R$53,6),'Estoque Atual'!$R$4:$R$53,0))),"") -> 2 | I13: =IFERROR(IF(LARGE('Estoque Atual'!$R$4:$R$53,6)<0,"",INDEX('Estoque Atual'!$J$4:$J$53,MATCH(LARGE('Estoque Atual'!$R$4:$R$53,6),'Estoque Atual'!$R$4:$R$53,0))),"") -> 0 | K13: =IFERROR(IF(SMALL('Estoque Atual'!$Q$4:$Q$53,6)>=999999,"",INDEX('Estoque Atual'!$A$4:$A$53,MATCH(SMALL('Estoque Atual'!$Q$4:$Q$53,6),'Estoque Atual'!$Q$4:$Q$53,0))),"") -> Cola bastão | L13: =IFERROR(IF(SMALL('Estoque Atual'!$Q$4:$Q$53,6)>=999999,"",INDEX('Estoque Atual'!$J$4:$J$53,MATCH(SMALL('Estoque Atual'!$Q$4:$Q$53,6),'Estoque Atual'!$Q$4:$Q$53,0))),"") -> 0 | M13: =IFERROR(IF(SMALL('Estoque Atual'!$Q$4:$Q$53,6)>=999999,"",INDEX('Estoque Atual'!$D$4:$D$53,MATCH(SMALL('Estoque Atual'!$Q$4:$Q$53,6),'Estoque Atual'!$Q$4:$Q$53,0))),"") -> 2 | N13: =IFERROR(IF(SMALL('Estoque Atual'!$Q$4:$Q$53,6)>=999999,"",INDEX('Estoque Atual'!$L$4:$L$53,MATCH(SMALL('Estoque Atual'!$Q$4:$Q$53,6),'Estoque Atual'!$Q$4:$Q$53,0))),"") -> ⚠ SEM ESTOQUE
A14: Julho | B14: =IFERROR(SUMIFS(Movimentações!$E$4:$E$5000,Movimentações!$B$4:$B$5000,">="&DATE(2026,7,1),Movimentações!$B$4:$B$5000,"<="&EOMONTH(DATE(2026,7,1),0),Movimentações!$D$4:$D$5000,"Entrada"),0) -> 0 | C14: =IFERROR(SUMIFS(Movimentações!$E$4:$E$5000,Movimentações!$B$4:$B$5000,">="&DATE(2026,7,1),Movimentações!$B$4:$B$5000,"<="&EOMONTH(DATE(2026,7,1),0),Movimentações!$D$4:$D$5000,"Saída"),0) -> 0 | D14: =B14-C14 -> 0 | F14: 7 | G14: =IFERROR(IF(LARGE('Estoque Atual'!$R$4:$R$53,7)<0,"",INDEX('Estoque Atual'!$A$4:$A$53,MATCH(LARGE('Estoque Atual'!$R$4:$R$53,7),'Estoque Atual'!$R$4:$R$53,0))),"") -> Bloco de notas | H14: =IFERROR(IF(LARGE('Estoque Atual'!$R$4:$R$53,7)<0,"",INDEX('Estoque Atual'!$I$4:$I$53,MATCH(LARGE('Estoque Atual'!$R$4:$R$53,7),'Estoque Atual'!$R$4:$R$53,0))),"") -> 2 | I14: =IFERROR(IF(LARGE('Estoque Atual'!$R$4:$R$53,7)<0,"",INDEX('Estoque Atual'!$J$4:$J$53,MATCH(LARGE('Estoque Atual'!$R$4:$R$53,7),'Estoque Atual'!$R$4:$R$53,0))),"") -> 13 | K14: =IFERROR(IF(SMALL('Estoque Atual'!$Q$4:$Q$53,7)>=999999,"",INDEX('Estoque Atual'!$A$4:$A$53,MATCH(SMALL('Estoque Atual'!$Q$4:$Q$53,7),'Estoque Atual'!$Q$4:$Q$53,0))),"") -> Tesoura | L14: =IFERROR(IF(SMALL('Estoque Atual'!$Q$4:$Q$53,7)>=999999,"",INDEX('Estoque Atual'!$J$4:$J$53,MATCH(SMALL('Estoque Atual'!$Q$4:$Q$53,7),'Estoque Atual'!$Q$4:$Q$53,0))),"") -> 0 | M14: =IFERROR(IF(SMALL('Estoque Atual'!$Q$4:$Q$53,7)>=999999,"",INDEX('Estoque Atual'!$D$4:$D$53,MATCH(SMALL('Estoque Atual'!$Q$4:$Q$53,7),'Estoque Atual'!$Q$4:$Q$53,0))),"") -> 2 | N14: =IFERROR(IF(SMALL('Estoque Atual'!$Q$4:$Q$53,7)>=999999,"",INDEX('Estoque Atual'!$L$4:$L$53,MATCH(SMALL('Estoque Atual'!$Q$4:$Q$53,7),'Estoque Atual'!$Q$4:$Q$53,0))),"") -> ⚠ SEM ESTOQUE
A15: Agosto | B15: =IFERROR(SUMIFS(Movimentações!$E$4:$E$5000,Movimentações!$B$4:$B$5000,">="&DATE(2026,8,1),Movimentações!$B$4:$B$5000,"<="&EOMONTH(DATE(2026,8,1),0),Movimentações!$D$4:$D$5000,"Entrada"),0) -> 0 | C15: =IFERROR(SUMIFS(Movimentações!$E$4:$E$5000,Movimentações!$B$4:$B$5000,">="&DATE(2026,8,1),Movimentações!$B$4:$B$5000,"<="&EOMONTH(DATE(2026,8,1),0),Movimentações!$D$4:$D$5000,"Saída"),0) -> 0 | D15: =B15-C15 -> 0 | F15: 8 | G15: =IFERROR(IF(LARGE('Estoque Atual'!$R$4:$R$53,8)<0,"",INDEX('Estoque Atual'!$A$4:$A$53,MATCH(LARGE('Estoque Atual'!$R$4:$R$53,8),'Estoque Atual'!$R$4:$R$53,0))),"") -> Bobina | H15: =IFERROR(IF(LARGE('Estoque Atual'!$R$4:$R$53,8)<0,"",INDEX('Estoque Atual'!$I$4:$I$53,MATCH(LARGE('Estoque Atual'!$R$4:$R$53,8),'Estoque Atual'!$R$4:$R$53,0))),"") -> 2 | I15: =IFERROR(IF(LARGE('Estoque Atual'!$R$4:$R$53,8)<0,"",INDEX('Estoque Atual'!$J$4:$J$53,MATCH(LARGE('Estoque Atual'!$R$4:$R$53,8),'Estoque Atual'!$R$4:$R$53,0))),"") -> 6 | K15: =IFERROR(IF(SMALL('Estoque Atual'!$Q$4:$Q$53,8)>=999999,"",INDEX('Estoque Atual'!$A$4:$A$53,MATCH(SMALL('Estoque Atual'!$Q$4:$Q$53,8),'Estoque Atual'!$Q$4:$Q$53,0))),"") -> Papel A3 | L15: =IFERROR(IF(SMALL('Estoque Atual'!$Q$4:$Q$53,8)>=999999,"",INDEX('Estoque Atual'!$J$4:$J$53,MATCH(SMALL('Estoque Atual'!$Q$4:$Q$53,8),'Estoque Atual'!$Q$4:$Q$53,0))),"") -> 0 | M15: =IFERROR(IF(SMALL('Estoque Atual'!$Q$4:$Q$53,8)>=999999,"",INDEX('Estoque Atual'!$D$4:$D$53,MATCH(SMALL('Estoque Atual'!$Q$4:$Q$53,8),'Estoque Atual'!$Q$4:$Q$53,0))),"") -> 2 | N15: =IFERROR(IF(SMALL('Estoque Atual'!$Q$4:$Q$53,8)>=999999,"",INDEX('Estoque Atual'!$L$4:$L$53,MATCH(SMALL('Estoque Atual'!$Q$4:$Q$53,8),'Estoque Atual'!$Q$4:$Q$53,0))),"") -> ⚠ SEM ESTOQUE
A16: Setembro | B16: =IFERROR(SUMIFS(Movimentações!$E$4:$E$5000,Movimentações!$B$4:$B$5000,">="&DATE(2026,9,1),Movimentações!$B$4:$B$5000,"<="&EOMONTH(DATE(2026,9,1),0),Movimentações!$D$4:$D$5000,"Entrada"),0) -> 0 | C16: =IFERROR(SUMIFS(Movimentações!$E$4:$E$5000,Movimentações!$B$4:$B$5000,">="&DATE(2026,9,1),Movimentações!$B$4:$B$5000,"<="&EOMONTH(DATE(2026,9,1),0),Movimentações!$D$4:$D$5000,"Saída"),0) -> 0 | D16: =B16-C16 -> 0 | F16: 9 | G16: =IFERROR(IF(LARGE('Estoque Atual'!$R$4:$R$53,9)<0,"",INDEX('Estoque Atual'!$A$4:$A$53,MATCH(LARGE('Estoque Atual'!$R$4:$R$53,9),'Estoque Atual'!$R$4:$R$53,0))),"") -> Clips | H16: =IFERROR(IF(LARGE('Estoque Atual'!$R$4:$R$53,9)<0,"",INDEX('Estoque Atual'!$I$4:$I$53,MATCH(LARGE('Estoque Atual'!$R$4:$R$53,9),'Estoque Atual'!$R$4:$R$53,0))),"") -> 1 | I16: =IFERROR(IF(LARGE('Estoque Atual'!$R$4:$R$53,9)<0,"",INDEX('Estoque Atual'!$J$4:$J$53,MATCH(LARGE('Estoque Atual'!$R$4:$R$53,9),'Estoque Atual'!$R$4:$R$53,0))),"") -> 3 | K16: =IFERROR(IF(SMALL('Estoque Atual'!$Q$4:$Q$53,9)>=999999,"",INDEX('Estoque Atual'!$A$4:$A$53,MATCH(SMALL('Estoque Atual'!$Q$4:$Q$53,9),'Estoque Atual'!$Q$4:$Q$53,0))),"") -> Cola | L16: =IFERROR(IF(SMALL('Estoque Atual'!$Q$4:$Q$53,9)>=999999,"",INDEX('Estoque Atual'!$J$4:$J$53,MATCH(SMALL('Estoque Atual'!$Q$4:$Q$53,9),'Estoque Atual'!$Q$4:$Q$53,0))),"") -> 1 | M16: =IFERROR(IF(SMALL('Estoque Atual'!$Q$4:$Q$53,9)>=999999,"",INDEX('Estoque Atual'!$D$4:$D$53,MATCH(SMALL('Estoque Atual'!$Q$4:$Q$53,9),'Estoque Atual'!$Q$4:$Q$53,0))),"") -> 2 | N16: =IFERROR(IF(SMALL('Estoque Atual'!$Q$4:$Q$53,9)>=999999,"",INDEX('Estoque Atual'!$L$4:$L$53,MATCH(SMALL('Estoque Atual'!$Q$4:$Q$53,9),'Estoque Atual'!$Q$4:$Q$53,0))),"") -> ⬇ ABAIXO DO MÍN.
A17: Outubro | B17: =IFERROR(SUMIFS(Movimentações!$E$4:$E$5000,Movimentações!$B$4:$B$5000,">="&DATE(2026,10,1),Movimentações!$B$4:$B$5000,"<="&EOMONTH(DATE(2026,10,1),0),Movimentações!$D$4:$D$5000,"Entrada"),0) -> 0 | C17: =IFERROR(SUMIFS(Movimentações!$E$4:$E$5000,Movimentações!$B$4:$B$5000,">="&DATE(2026,10,1),Movimentações!$B$4:$B$5000,"<="&EOMONTH(DATE(2026,10,1),0),Movimentações!$D$4:$D$5000,"Saída"),0) -> 0 | D17: =B17-C17 -> 0 | F17: 10 | G17: =IFERROR(IF(LARGE('Estoque Atual'!$R$4:$R$53,10)<0,"",INDEX('Estoque Atual'!$A$4:$A$53,MATCH(LARGE('Estoque Atual'!$R$4:$R$53,10),'Estoque Atual'!$R$4:$R$53,0))),"") | H17: =IFERROR(IF(LARGE('Estoque Atual'!$R$4:$R$53,10)<0,"",INDEX('Estoque Atual'!$I$4:$I$53,MATCH(LARGE('Estoque Atual'!$R$4:$R$53,10),'Estoque Atual'!$R$4:$R$53,0))),"") | I17: =IFERROR(IF(LARGE('Estoque Atual'!$R$4:$R$53,10)<0,"",INDEX('Estoque Atual'!$J$4:$J$53,MATCH(LARGE('Estoque Atual'!$R$4:$R$53,10),'Estoque Atual'!$R$4:$R$53,0))),"") | K17: =IFERROR(IF(SMALL('Estoque Atual'!$Q$4:$Q$53,10)>=999999,"",INDEX('Estoque Atual'!$A$4:$A$53,MATCH(SMALL('Estoque Atual'!$Q$4:$Q$53,10),'Estoque Atual'!$Q$4:$Q$53,0))),"") -> Grampo normal | L17: =IFERROR(IF(SMALL('Estoque Atual'!$Q$4:$Q$53,10)>=999999,"",INDEX('Estoque Atual'!$J$4:$J$53,MATCH(SMALL('Estoque Atual'!$Q$4:$Q$53,10),'Estoque Atual'!$Q$4:$Q$53,0))),"") -> 0 | M17: =IFERROR(IF(SMALL('Estoque Atual'!$Q$4:$Q$53,10)>=999999,"",INDEX('Estoque Atual'!$D$4:$D$53,MATCH(SMALL('Estoque Atual'!$Q$4:$Q$53,10),'Estoque Atual'!$Q$4:$Q$53,0))),"") -> 1 | N17: =IFERROR(IF(SMALL('Estoque Atual'!$Q$4:$Q$53,10)>=999999,"",INDEX('Estoque Atual'!$L$4:$L$53,MATCH(SMALL('Estoque Atual'!$Q$4:$Q$53,10),'Estoque Atual'!$Q$4:$Q$53,0))),"") -> ⚠ SEM ESTOQUE
A18: Novembro | B18: =IFERROR(SUMIFS(Movimentações!$E$4:$E$5000,Movimentações!$B$4:$B$5000,">="&DATE(2026,11,1),Movimentações!$B$4:$B$5000,"<="&EOMONTH(DATE(2026,11,1),0),Movimentações!$D$4:$D$5000,"Entrada"),0) -> 0 | C18: =IFERROR(SUMIFS(Movimentações!$E$4:$E$5000,Movimentações!$B$4:$B$5000,">="&DATE(2026,11,1),Movimentações!$B$4:$B$5000,"<="&EOMONTH(DATE(2026,11,1),0),Movimentações!$D$4:$D$5000,"Saída"),0) -> 0 | D18: =B18-C18 -> 0
A19: Dezembro | B19: =IFERROR(SUMIFS(Movimentações!$E$4:$E$5000,Movimentações!$B$4:$B$5000,">="&DATE(2026,12,1),Movimentações!$B$4:$B$5000,"<="&EOMONTH(DATE(2026,12,1),0),Movimentações!$D$4:$D$5000,"Entrada"),0) -> 0 | C19: =IFERROR(SUMIFS(Movimentações!$E$4:$E$5000,Movimentações!$B$4:$B$5000,">="&DATE(2026,12,1),Movimentações!$B$4:$B$5000,"<="&EOMONTH(DATE(2026,12,1),0),Movimentações!$D$4:$D$5000,"Saída"),0) -> 0 | D19: =B19-C19 -> 0
A20: TOTAL | B20: =SUM(B8:B19) -> 322 | C20: =SUM(C8:C19) -> 290 | D20: =SUM(D8:D19) -> 32
A22: 👥 COLABORADORES — RETIRADAS 2026
A23: Colaborador | B23: Departamento | C23: Saídas | D23: Itens Únicos | E23: Últ. Retirada
A24: Amanda Silva | B24: =IFERROR(VLOOKUP(A24,'Cad. Colaboradores'!$B$4:$C$17,2,FALSE),"") -> Administrativo | C24: =IFERROR(SUMIFS(Movimentações!$E$4:$E$5000,Movimentações!$F$4:$F$5000,A24,Movimentações!$D$4:$D$5000,"Saída"),0) -> 1 | D24: =SUMPRODUCT((COUNTIFS(Movimentações!$F$4:$F$5000,A24,Movimentações!$C$4:$C$5000,'Estoque Atual'!$A$4:$A$53,Movimentações!$D$4:$D$5000,"Saída")>0)*1) -> 1 | E24: =IF(COUNTIFS(Movimentações!$F$4:$F$5000,A24,Movimentações!$D$4:$D$5000,"Saída")=0,"",SUMPRODUCT(MAX((Movimentações!$F$4:$F$5000=A24)*(Movimentações!$D$4:$D$5000="Saída")*Movimentações!$B$4:$B$5000))) -> 46099
A25: André Souza | B25: =IFERROR(VLOOKUP(A25,'Cad. Colaboradores'!$B$4:$C$17,2,FALSE),"") -> Administrativo | C25: =IFERROR(SUMIFS(Movimentações!$E$4:$E$5000,Movimentações!$F$4:$F$5000,A25,Movimentações!$D$4:$D$5000,"Saída"),0) -> 2 | D25: =SUMPRODUCT((COUNTIFS(Movimentações!$F$4:$F$5000,A25,Movimentações!$C$4:$C$5000,'Estoque Atual'!$A$4:$A$53,Movimentações!$D$4:$D$5000,"Saída")>0)*1) -> 2 | E25: =IF(COUNTIFS(Movimentações!$F$4:$F$5000,A25,Movimentações!$D$4:$D$5000,"Saída")=0,"",SUMPRODUCT(MAX((Movimentações!$F$4:$F$5000=A25)*(Movimentações!$D$4:$D$5000="Saída")*Movimentações!$B$4:$B$5000))) -> 46114
A26: Ariane Costa | B26: =IFERROR(VLOOKUP(A26,'Cad. Colaboradores'!$B$4:$C$17,2,FALSE),"") -> Administrativo | C26: =IFERROR(SUMIFS(Movimentações!$E$4:$E$5000,Movimentações!$F$4:$F$5000,A26,Movimentações!$D$4:$D$5000,"Saída"),0) -> 42 | D26: =SUMPRODUCT((COUNTIFS(Movimentações!$F$4:$F$5000,A26,Movimentações!$C$4:$C$5000,'Estoque Atual'!$A$4:$A$53,Movimentações!$D$4:$D$5000,"Saída")>0)*1) -> 5 | E26: =IF(COUNTIFS(Movimentações!$F$4:$F$5000,A26,Movimentações!$D$4:$D$5000,"Saída")=0,"",SUMPRODUCT(MAX((Movimentações!$F$4:$F$5000=A26)*(Movimentações!$D$4:$D$5000="Saída")*Movimentações!$B$4:$B$5000))) -> 46092
A27: Beatriz Lima | B27: =IFERROR(VLOOKUP(A27,'Cad. Colaboradores'!$B$4:$C$17,2,FALSE),"") -> Administrativo | C27: =IFERROR(SUMIFS(Movimentações!$E$4:$E$5000,Movimentações!$F$4:$F$5000,A27,Movimentações!$D$4:$D$5000,"Saída"),0) -> 61 | D27: =SUMPRODUCT((COUNTIFS(Movimentações!$F$4:$F$5000,A27,Movimentações!$C$4:$C$5000,'Estoque Atual'!$A$4:$A$53,Movimentações!$D$4:$D$5000,"Saída")>0)*1) -> 5 | E27: =IF(COUNTIFS(Movimentações!$F$4:$F$5000,A27,Movimentações!$D$4:$D$5000,"Saída")=0,"",SUMPRODUCT(MAX((Movimentações!$F$4:$F$5000=A27)*(Movimentações!$D$4:$D$5000="Saída")*Movimentações!$B$4:$B$5000))) -> 46113
A28: Camila Rocha | B28: =IFERROR(VLOOKUP(A28,'Cad. Colaboradores'!$B$4:$C$17,2,FALSE),"") -> Administrativo | C28: =IFERROR(SUMIFS(Movimentações!$E$4:$E$5000,Movimentações!$F$4:$F$5000,A28,Movimentações!$D$4:$D$5000,"Saída"),0) -> 3 | D28: =SUMPRODUCT((COUNTIFS(Movimentações!$F$4:$F$5000,A28,Movimentações!$C$4:$C$5000,'Estoque Atual'!$A$4:$A$53,Movimentações!$D$4:$D$5000,"Saída")>0)*1) -> 1 | E28: =IF(COUNTIFS(Movimentações!$F$4:$F$5000,A28,Movimentações!$D$4:$D$5000,"Saída")=0,"",SUMPRODUCT(MAX((Movimentações!$F$4:$F$5000=A28)*(Movimentações!$D$4:$D$5000="Saída")*Movimentações!$B$4:$B$5000))) -> 46026
A29: Érica Felipe | B29: =IFERROR(VLOOKUP(A29,'Cad. Colaboradores'!$B$4:$C$17,2,FALSE),"") -> Administrativo | C29: =IFERROR(SUMIFS(Movimentações!$E$4:$E$5000,Movimentações!$F$4:$F$5000,A29,Movimentações!$D$4:$D$5000,"Saída"),0) -> 22 | D29: =SUMPRODUCT((COUNTIFS(Movimentações!$F$4:$F$5000,A29,Movimentações!$C$4:$C$5000,'Estoque Atual'!$A$4:$A$53,Movimentações!$D$4:$D$5000,"Saída")>0)*1) -> 4 | E29: =IF(COUNTIFS(Movimentações!$F$4:$F$5000,A29,Movimentações!$D$4:$D$5000,"Saída")=0,"",SUMPRODUCT(MAX((Movimentações!$F$4:$F$5000=A29)*(Movimentações!$D$4:$D$5000="Saída")*Movimentações!$B$4:$B$5000))) -> 46125
A30: Larissa Mendes | B30: =IFERROR(VLOOKUP(A30,'Cad. Colaboradores'!$B$4:$C$17,2,FALSE),"") -> Administrativo | C30: =IFERROR(SUMIFS(Movimentações!$E$4:$E$5000,Movimentações!$F$4:$F$5000,A30,Movimentações!$D$4:$D$5000,"Saída"),0) -> 107 | D30: =SUMPRODUCT((COUNTIFS(Movimentações!$F$4:$F$5000,A30,Movimentações!$C$4:$C$5000,'Estoque Atual'!$A$4:$A$53,Movimentações!$D$4:$D$5000,"Saída")>0)*1) -> 2 | E30: =IF(COUNTIFS(Movimentações!$F$4:$F$5000,A30,Movimentações!$D$4:$D$5000,"Saída")=0,"",SUMPRODUCT(MAX((Movimentações!$F$4:$F$5000=A30)*(Movimentações!$D$4:$D$5000="Saída")*Movimentações!$B$4:$B$5000))) -> 46122
A31: Laura Ribeiro | B31: =IFERROR(VLOOKUP(A31,'Cad. Colaboradores'!$B$4:$C$17,2,FALSE),"") -> Compras | C31: =IFERROR(SUMIFS(Movimentações!$E$4:$E$5000,Movimentações!$F$4:$F$5000,A31,Movimentações!$D$4:$D$5000,"Saída"),0) -> 9 | D31: =SUMPRODUCT((COUNTIFS(Movimentações!$F$4:$F$5000,A31,Movimentações!$C$4:$C$5000,'Estoque Atual'!$A$4:$A$53,Movimentações!$D$4:$D$5000,"Saída")>0)*1) -> 5 | E31: =IF(COUNTIFS(Movimentações!$F$4:$F$5000,A31,Movimentações!$D$4:$D$5000,"Saída")=0,"",SUMPRODUCT(MAX((Movimentações!$F$4:$F$5000=A31)*(Movimentações!$D$4:$D$5000="Saída")*Movimentações!$B$4:$B$5000))) -> 46122
A32: Liliana Santos | B32: =IFERROR(VLOOKUP(A32,'Cad. Colaboradores'!$B$4:$C$17,2,FALSE),"") -> Administrativo | C32: =IFERROR(SUMIFS(Movimentações!$E$4:$E$5000,Movimentações!$F$4:$F$5000,A32,Movimentações!$D$4:$D$5000,"Saída"),0) -> 2 | D32: =SUMPRODUCT((COUNTIFS(Movimentações!$F$4:$F$5000,A32,Movimentações!$C$4:$C$5000,'Estoque Atual'!$A$4:$A$53,Movimentações!$D$4:$D$5000,"Saída")>0)*1) -> 2 | E32: =IF(COUNTIFS(Movimentações!$F$4:$F$5000,A32,Movimentações!$D$4:$D$5000,"Saída")=0,"",SUMPRODUCT(MAX((Movimentações!$F$4:$F$5000=A32)*(Movimentações!$D$4:$D$5000="Saída")*Movimentações!$B$4:$B$5000))) -> 46084
A33: Lucas Pereira | B33: =IFERROR(VLOOKUP(A33,'Cad. Colaboradores'!$B$4:$C$17,2,FALSE),"") -> Operacional | C33: =IFERROR(SUMIFS(Movimentações!$E$4:$E$5000,Movimentações!$F$4:$F$5000,A33,Movimentações!$D$4:$D$5000,"Saída"),0) -> 3 | D33: =SUMPRODUCT((COUNTIFS(Movimentações!$F$4:$F$5000,A33,Movimentações!$C$4:$C$5000,'Estoque Atual'!$A$4:$A$53,Movimentações!$D$4:$D$5000,"Saída")>0)*1) -> 3 | E33: =IF(COUNTIFS(Movimentações!$F$4:$F$5000,A33,Movimentações!$D$4:$D$5000,"Saída")=0,"",SUMPRODUCT(MAX((Movimentações!$F$4:$F$5000=A33)*(Movimentações!$D$4:$D$5000="Saída")*Movimentações!$B$4:$B$5000))) -> 46119
A34: Matheus Alves | B34: =IFERROR(VLOOKUP(A34,'Cad. Colaboradores'!$B$4:$C$17,2,FALSE),"") -> Administrativo | C34: =IFERROR(SUMIFS(Movimentações!$E$4:$E$5000,Movimentações!$F$4:$F$5000,A34,Movimentações!$D$4:$D$5000,"Saída"),0) -> 26 | D34: =SUMPRODUCT((COUNTIFS(Movimentações!$F$4:$F$5000,A34,Movimentações!$C$4:$C$5000,'Estoque Atual'!$A$4:$A$53,Movimentações!$D$4:$D$5000,"Saída")>0)*1) -> 3 | E34: =IF(COUNTIFS(Movimentações!$F$4:$F$5000,A34,Movimentações!$D$4:$D$5000,"Saída")=0,"",SUMPRODUCT(MAX((Movimentações!$F$4:$F$5000=A34)*(Movimentações!$D$4:$D$5000="Saída")*Movimentações!$B$4:$B$5000))) -> 46147
A35: Pedro Cardoso | B35: =IFERROR(VLOOKUP(A35,'Cad. Colaboradores'!$B$4:$C$17,2,FALSE),"") -> Administrativo | C35: =IFERROR(SUMIFS(Movimentações!$E$4:$E$5000,Movimentações!$F$4:$F$5000,A35,Movimentações!$D$4:$D$5000,"Saída"),0) -> 1 | D35: =SUMPRODUCT((COUNTIFS(Movimentações!$F$4:$F$5000,A35,Movimentações!$C$4:$C$5000,'Estoque Atual'!$A$4:$A$53,Movimentações!$D$4:$D$5000,"Saída")>0)*1) -> 1 | E35: =IF(COUNTIFS(Movimentações!$F$4:$F$5000,A35,Movimentações!$D$4:$D$5000,"Saída")=0,"",SUMPRODUCT(MAX((Movimentações!$F$4:$F$5000=A35)*(Movimentações!$D$4:$D$5000="Saída")*Movimentações!$B$4:$B$5000))) -> 46027
... A37: Ronan Oliveira | B37: =IFERROR(VLOOKUP(A37,'Cad. Colaboradores'!$B$4:$C$17,2,FALSE),"") -> Compras | C37: =IFERROR(SUMIFS(Movimentações!$E$4:$E$5000,Movimentações!$F$4:$F$5000,A37,Movimentações!$D$4:$D$5000,"Saída"),0) -> 0 | D37: =SUMPRODUCT((COUNTIFS(Movimentações!$F$4:$F$5000,A37,Movimentações!$C$4:$C$5000,'Estoque Atual'!$A$4:$A$53,Movimentações!$D$4:$D$5000,"Saída")>0)*1) -> 0 | E37: =IF(COUNTIFS(Movimentações!$F$4:$F$5000,A37,Movimentações!$D$4:$D$5000,"Saída")=0,"",SUMPRODUCT(MAX((Movimentações!$F$4:$F$5000=A37)*(Movimentações!$D$4:$D$5000="Saída")*Movimentações!$B$4:$B$5000)))
A38: TOTAL | C38: =SUM(C24:C37) -> 290

Sheet Estoque Atual
A1: 📦 ESTOQUE ATUAL — CÁLCULO AUTOMÁTICO
A2: ℹ️ Os dados desta aba são calculados automaticamente. Para alterar custo, mínimo ou lead time, edite 'Cad. Materiais'.
A3: Material | B3: Categoria | C3: Unidade | D3: Est. Mín. | E3: Est. Inicial | F3: Custo Unit. | G3: Lead Time | H3: Entradas | I3: Saídas | J3: Estoque Atual | K3: Valor em Estoque | L3: Status | M3: Consumo/Dia | N3: Dias até Zerar | O3: Ponto de Reposição | P3: Últ. Movim.
A4: =IF('Cad. Materiais'!B4="","",'Cad. Materiais'!B4) -> Resma de papel A4 | B4: =IFERROR(VLOOKUP(A4,'Cad. Materiais'!$B$4:$D$53,3,FALSE),"") -> Papel/Impressão | C4: =IFERROR(VLOOKUP(A4,'Cad. Materiais'!$B$4:$C$53,2,FALSE),"") -> Unidade | D4: =IFERROR(VLOOKUP(A4,'Cad. Materiais'!$B$4:$E$53,4,FALSE),0) -> 5 | E4: =IFERROR(VLOOKUP(A4,'Cad. Materiais'!$B$4:$F$53,5,FALSE),0) -> 16 | F4: =IFERROR(VLOOKUP(A4,'Cad. Materiais'!$B$4:$G$53,6,FALSE),0) -> 28.5 | G4: =IFERROR(VLOOKUP(A4,'Cad. Materiais'!$B$4:$H$53,7,FALSE),0) -> 7 | H4: =IFERROR(SUMIFS(Movimentações!$E$4:$E$5000,Movimentações!$C$4:$C$5000,A4,Movimentações!$D$4:$D$5000,"Entrada"),0) -> 46 | I4: =IFERROR(SUMIFS(Movimentações!$E$4:$E$5000,Movimentações!$C$4:$C$5000,A4,Movimentações!$D$4:$D$5000,"Saída"),0) -> 56 | J4: =IF(A4="","",E4+H4-I4) -> 6 | K4: =IF(A4="","",J4*F4) -> 171 | L4: =IF(A4="","",IF(J4<=0,"⚠ SEM ESTOQUE",IF(J4<D4,"⬇ ABAIXO DO MÍN.",IF(J4<D4*1.5,"➡ ATENÇÃO","✔ NORMAL")))) -> ➡ ATENÇÃO | M4: =IF(I4=0,0,IFERROR(I4/MAX(1,SUMPRODUCT(MAX((Movimentações!$C$4:$C$5000=A4)*(Movimentações!$D$4:$D$5000="Saída")*Movimentações!$B$4:$B$5000))-SUMPRODUCT(MIN(IF((Movimentações!$C$4:$C$5000=A4)*(Movimentações!$D$4:$D$5000="Saída")=1,Movimentações!$B$4:$B$5000)))+1),0)) -> 0.45528455 | N4: =IF(M4<=0,"-",IF(J4<=0,0,ROUND(J4/M4,0))) -> 13 | O4: =ROUND(M4*G4+D4,0) -> 8 | P4: =IF(A4="","",IF(COUNTIF(Movimentações!$C$4:$C$5000,A4)=0,"Sem movim.",SUMPRODUCT(MAX((Movimentações!$C$4:$C$5000=A4)*Movimentações!$B$4:$B$5000)))) -> 46147 | Q4: =IF(OR(L4="✔ NORMAL",L4="",A4=""),999999,(J4-D4)+ROW()/100000) -> 1.00004 | R4: =IF(I4=0,-ROW()/100000,I4+(1-ROW()/100000)) -> 56.99996
A5: =IF('Cad. Materiais'!B5="","",'Cad. Materiais'!B5) -> Envelope Pardo | B5: =IFERROR(VLOOKUP(A5,'Cad. Materiais'!$B$4:$D$53,3,FALSE),"") -> Envelopes | C5: =IFERROR(VLOOKUP(A5,'Cad. Materiais'!$B$4:$C$53,2,FALSE),"") -> Unidade | D5: =IFERROR(VLOOKUP(A5,'Cad. Materiais'!$B$4:$E$53,4,FALSE),0) -> 10 | E5: =IFERROR(VLOOKUP(A5,'Cad. Materiais'!$B$4:$F$53,5,FALSE),0) -> 5 | F5: =IFERROR(VLOOKUP(A5,'Cad. Materiais'!$B$4:$G$53,6,FALSE),0) -> 0.8 | G5: =IFERROR(VLOOKUP(A5,'Cad. Materiais'!$B$4:$H$53,7,FALSE),0) -> 5 | H5: =IFERROR(SUMIFS(Movimentações!$E$4:$E$5000,Movimentações!$C$4:$C$5000,A5,Movimentações!$D$4:$D$5000,"Entrada"),0) -> 200 | I5: =IFERROR(SUMIFS(Movimentações!$E$4:$E$5000,Movimentações!$C$4:$C$5000,A5,Movimentações!$D$4:$D$5000,"Saída"),0) -> 20 | J5: =IF(A5="","",E5+H5-I5) -> 185 | K5: =IF(A5="","",J5*F5) -> 148 | L5: =IF(A5="","",IF(J5<=0,"⚠ SEM ESTOQUE",IF(J5<D5,"⬇ ABAIXO DO MÍN.",IF(J5<D5*1.5,"➡ ATENÇÃO","✔ NORMAL")))) -> ✔ NORMAL | M5: =IF(I5=0,0,IFERROR(I5/MAX(1,SUMPRODUCT(MAX((Movimentações!$C$4:$C$5000=A5)*(Movimentações!$D$4:$D$5000="Saída")*Movimentações!$B$4:$B$5000))-SUMPRODUCT(MIN(IF((Movimentações!$C$4:$C$5000=A5)*(Movimentações!$D$4:$D$5000="Saída")=1,Movimentações!$B$4:$B$5000)))+1),0)) -> 0.00043359494 | N5: =IF(M5<=0,"-",IF(J5<=0,0,ROUND(J5/M5,0))) -> 426666 | O5: =ROUND(M5*G5+D5,0) -> 10 | P5: =IF(A5="","",IF(COUNTIF(Movimentações!$C$4:$C$5000,A5)=0,"Sem movim.",SUMPRODUCT(MAX((Movimentações!$C$4:$C$5000=A5)*Movimentações!$B$4:$B$5000)))) -> 46125 | Q5: =IF(OR(L5="✔ NORMAL",L5="",A5=""),999999,(J5-D5)+ROW()/100000) -> 999999 | R5: =IF(I5=0,-ROW()/100000,I5+(1-ROW()/100000)) -> 20.99995
A6: =IF('Cad. Materiais'!B6="","",'Cad. Materiais'!B6) -> Clips | B6: =IFERROR(VLOOKUP(A6,'Cad. Materiais'!$B$4:$D$53,3,FALSE),"") -> Escritório | C6: =IFERROR(VLOOKUP(A6,'Cad. Materiais'!$B$4:$C$53,2,FALSE),"") -> Caixa | D6: =IFERROR(VLOOKUP(A6,'Cad. Materiais'!$B$4:$E$53,4,FALSE),0) -> 2 | E6: =IFERROR(VLOOKUP(A6,'Cad. Materiais'!$B$4:$F$53,5,FALSE),0) -> 4 | F6: =IFERROR(VLOOKUP(A6,'Cad. Materiais'!$B$4:$G$53,6,FALSE),0) -> 8.9 | G6: =IFERROR(VLOOKUP(A6,'Cad. Materiais'!$B$4:$H$53,7,FALSE),0) -> 5 | H6: =IFERROR(SUMIFS(Movimentações!$E$4:$E$5000,Movimentações!$C$4:$C$5000,A6,Movimentações!$D$4:$D$5000,"Entrada"),0) -> 0 | I6: =IFERROR(SUMIFS(Movimentações!$E$4:$E$5000,Movimentações!$C$4:$C$5000,A6,Movimentações!$D$4:$D$5000,"Saída"),0) -> 1 | J6: =IF(A6="","",E6+H6-I6) -> 3 | K6: =IF(A6="","",J6*F6) -> 26.7 | L6: =IF(A6="","",IF(J6<=0,"⚠ SEM ESTOQUE",IF(J6<D6,"⬇ ABAIXO DO MÍN.",IF(J6<D6*1.5,"➡ ATENÇÃO","✔ NORMAL")))) -> ✔ NORMAL | M6: =IF(I6=0,0,IFERROR(I6/MAX(1,SUMPRODUCT(MAX((Movimentações!$C$4:$C$5000=A6)*(Movimentações!$D$4:$D$5000="Saída")*Movimentações!$B$4:$B$5000))-SUMPRODUCT(MIN(IF((Movimentações!$C$4:$C$5000=A6)*(Movimentações!$D$4:$D$5000="Saída")=1,Movimentações!$B$4:$B$5000)))+1),0)) -> 2.172685e-05 | N6: =IF(M6<=0,"-",IF(J6<=0,0,ROUND(J6/M6,0))) -> 138078 | O6: =ROUND(M6*G6+D6,0) -> 2 | P6: =IF(A6="","",IF(COUNTIF(Movimentações!$C$4:$C$5000,A6)=0,"Sem movim.",SUMPRODUCT(MAX((Movimentações!$C$4:$C$5000=A6)*Movimentações!$B$4:$B$5000)))) -> 46025 | Q6: =IF(OR(L6="✔ NORMAL",L6="",A6=""),999999,(J6-D6)+ROW()/100000) -> 999999 | R6: =IF(I6=0,-ROW()/100000,I6+(1-ROW()/100000)) -> 1.99994
A7: =IF('Cad. Materiais'!B7="","",'Cad. Materiais'!B7) -> Envelope Janelado | B7: =IFERROR(VLOOKUP(A7,'Cad. Materiais'!$B$4:$D$53,3,FALSE),"") -> Envelopes | C7: =IFERROR(VLOOKUP(A7,'Cad. Materiais'!$B$4:$C$53,2,FALSE),"") -> Unidade | D7: =IFERROR(VLOOKUP(A7,'Cad. Materiais'!$B$4:$E$53,4,FALSE),0) -> 50 | E7: =IFERROR(VLOOKUP(A7,'Cad. Materiais'!$B$4:$F$53,5,FALSE),0) -> 500 | F7: =IFERROR(VLOOKUP(A7,'Cad. Materiais'!$B$4:$G$53,6,FALSE),0) -> 0.45 | G7: =IFERROR(VLOOKUP(A7,'Cad. Materiais'!$B$4:$H$53,7,FALSE),0) -> 10 | H7: =IFERROR(SUMIFS(Movimentações!$E$4:$E$5000,Movimentações!$C$4:$C$5000,A7,Movimentações!$D$4:$D$5000,"Entrada"),0) -> 0 | I7: =IFERROR(SUMIFS(Movimentações!$E$4:$E$5000,Movimentações!$C$4:$C$5000,A7,Movimentações!$D$4:$D$5000,"Saída"),0) -> 198 | J7: =IF(A7="","",E7+H7-I7) -> 302 | K7: =IF(A7="","",J7*F7) -> 135.9 | L7: =IF(A7="","",IF(J7<=0,"⚠ SEM ESTOQUE",IF(J7<D7,"⬇ ABAIXO DO MÍN.",IF(J7<D7*1.5,"➡ ATENÇÃO","✔ NORMAL")))) -> ✔ NORMAL | M7: =IF(I7=0,0,IFERROR(I7/MAX(1,SUMPRODUCT(MAX((Movimentações!$C$4:$C$5000=A7)*(Movimentações!$D$4:$D$5000="Saída")*Movimentações!$B$4:$B$5000))-SUMPRODUCT(MIN(IF((Movimentações!$C$4:$C$5000=A7)*(Movimentações!$D$4:$D$5000="Saída")=1,Movimentações!$B$4:$B$5000)))+1),0)) -> 0.0042938931 | N7: =IF(M7<=0,"-",IF(J7<=0,0,ROUND(J7/M7,0))) -> 70332 | O7: =ROUND(M7*G7+D7,0) -> 50 | P7: =IF(A7="","",IF(COUNTIF(Movimentações!$C$4:$C$5000,A7)=0,"Sem movim.",SUMPRODUCT(MAX((Movimentações!$C$4:$C$5000=A7)*Movimentações!$B$4:$B$5000)))) -> 46111 | Q7: =IF(OR(L7="✔ NORMAL",L7="",A7=""),999999,(J7-D7)+ROW()/100000) -> 999999 | R7: =IF(I7=0,-ROW()/100000,I7+(1-ROW()/100000)) -> 198.99993
A8: =IF('Cad. Materiais'!B8="","",'Cad. Materiais'!B8) -> Post-IT | B8: =IFERROR(VLOOKUP(A8,'Cad. Materiais'!$B$4:$D$53,3,FALSE),"") -> Escritório | C8: =IFERROR(VLOOKUP(A8,'Cad. Materiais'!$B$4:$C$53,2,FALSE),"") -> Unidade | D8: =IFERROR(VLOOKUP(A8,'Cad. Materiais'!$B$4:$E$53,4,FALSE),0) -> 2 | E8: =IFERROR(VLOOKUP(A8,'Cad. Materiais'!$B$4:$F$53,5,FALSE),0) -> 0 | F8: =IFERROR(VLOOKUP(A8,'Cad. Materiais'!$B$4:$G$53,6,FALSE),0) -> 12.5 | G8: =IFERROR(VLOOKUP(A8,'Cad. Materiais'!$B$4:$H$53,7,FALSE),0) -> 7 | H8: =IFERROR(SUMIFS(Movimentações!$E$4:$E$5000,Movimentações!$C$4:$C$5000,A8,Movimentações!$D$4:$D$5000,"Entrada"),0) -> 0 | I8: =IFERROR(SUMIFS(Movimentações!$E$4:$E$5000,Movimentações!$C$4:$C$5000,A8,Movimentações!$D$4:$D$5000,"Saída"),0) -> 0 | J8: =IF(A8="","",E8+H8-I8) -> 0 | K8: =IF(A8="","",J8*F8) -> 0 | L8: =IF(A8="","",IF(J8<=0,"⚠ SEM ESTOQUE",IF(J8<D8,"⬇ ABAIXO DO MÍN.",IF(J8<D8*1.5,"➡ ATENÇÃO","✔ NORMAL")))) -> ⚠ SEM ESTOQUE | M8: =IF(I8=0,0,IFERROR(I8/MAX(1,SUMPRODUCT(MAX((Movimentações!$C$4:$C$5000=A8)*(Movimentações!$D$4:$D$5000="Saída")*Movimentações!$B$4:$B$5000))-SUMPRODUCT(MIN(IF((Movimentações!$C$4:$C$5000=A8)*(Movimentações!$D$4:$D$5000="Saída")=1,Movimentações!$B$4:$B$5000)))+1),0)) -> 0 | N8: =IF(M8<=0,"-",IF(J8<=0,0,ROUND(J8/M8,0))) -> - | O8: =ROUND(M8*G8+D8,0) -> 2 | P8: =IF(A8="","",IF(COUNTIF(Movimentações!$C$4:$C$5000,A8)=0,"Sem movim.",SUMPRODUCT(MAX((Movimentações!$C$4:$C$5000=A8)*Movimentações!$B$4:$B$5000)))) -> Sem movim. | Q8: =IF(OR(L8="✔ NORMAL",L8="",A8=""),999999,(J8-D8)+ROW()/100000) -> -1.99992 | R8: =IF(I8=0,-ROW()/100000,I8+(1-ROW()/100000)) -> -8e-05
A9: =IF('Cad. Materiais'!B9="","",'Cad. Materiais'!B9) -> Marcador de texto | B9: =IFERROR(VLOOKUP(A9,'Cad. Materiais'!$B$4:$D$53,3,FALSE),"") -> Escritório | C9: =IFERROR(VLOOKUP(A9,'Cad. Materiais'!$B$4:$C$53,2,FALSE),"") -> Unidade | D9: =IFERROR(VLOOKUP(A9,'Cad. Materiais'!$B$4:$E$53,4,FALSE),0) -> 2 | E9: =IFERROR(VLOOKUP(A9,'Cad. Materiais'!$B$4:$F$53,5,FALSE),0) -> 0 | F9: =IFERROR(VLOOKUP(A9,'Cad. Materiais'!$B$4:$G$53,6,FALSE),0) -> 4.2 | G9: =IFERROR(VLOOKUP(A9,'Cad. Materiais'!$B$4:$H$53,7,FALSE),0) -> 7 | H9: =IFERROR(SUMIFS(Movimentações!$E$4:$E$5000,Movimentações!$C$4:$C$5000,A9,Movimentações!$D$4:$D$5000,"Entrada"),0) -> 0 | I9: =IFERROR(SUMIFS(Movimentações!$E$4:$E$5000,Movimentações!$C$4:$C$5000,A9,Movimentações!$D$4:$D$5000,"Saída"),0) -> 0 | J9: =IF(A9="","",E9+H9-I9) -> 0 | K9: =IF(A9="","",J9*F9) -> 0 | L9: =IF(A9="","",IF(J9<=0,"⚠ SEM ESTOQUE",IF(J9<D9,"⬇ ABAIXO DO MÍN.",IF(J9<D9*1.5,"➡ ATENÇÃO","✔ NORMAL")))) -> ⚠ SEM ESTOQUE | M9: =IF(I9=0,0,IFERROR(I9/MAX(1,SUMPRODUCT(MAX((Movimentações!$C$4:$C$5000=A9)*(Movimentações!$D$4:$D$5000="Saída")*Movimentações!$B$4:$B$5000))-SUMPRODUCT(MIN(IF((Movimentações!$C$4:$C$5000=A9)*(Movimentações!$D$4:$D$5000="Saída")=1,Movimentações!$B$4:$B$5000)))+1),0)) -> 0 | N9: =IF(M9<=0,"-",IF(J9<=0,0,ROUND(J9/M9,0))) -> - | O9: =ROUND(M9*G9+D9,0) -> 2 | P9: =IF(A9="","",IF(COUNTIF(Movimentações!$C$4:$C$5000,A9)=0,"Sem movim.",SUMPRODUCT(MAX((Movimentações!$C$4:$C$5000=A9)*Movimentações!$B$4:$B$5000)))) -> Sem movim. | Q9: =IF(OR(L9="✔ NORMAL",L9="",A9=""),999999,(J9-D9)+ROW()/100000) -> -1.99991 | R9: =IF(I9=0,-ROW()/100000,I9+(1-ROW()/100000)) -> -9e-05
A10: =IF('Cad. Materiais'!B10="","",'Cad. Materiais'!B10) -> Caneta Azul | B10: =IFERROR(VLOOKUP(A10,'Cad. Materiais'!$B$4:$D$53,3,FALSE),"") -> Escritório | C10: =IFERROR(VLOOKUP(A10,'Cad. Materiais'!$B$4:$C$53,2,FALSE),"") -> Unidade | D10: =IFERROR(VLOOKUP(A10,'Cad. Materiais'!$B$4:$E$53,4,FALSE),0) -> 5 | E10: =IFERROR(VLOOKUP(A10,'Cad. Materiais'!$B$4:$F$53,5,FALSE),0) -> 0 | F10: =IFERROR(VLOOKUP(A10,'Cad. Materiais'!$B$4:$G$53,6,FALSE),0) -> 2.8 | G10: =IFERROR(VLOOKUP(A10,'Cad. Materiais'!$B$4:$H$53,7,FALSE),0) -> 3 | H10: =IFERROR(SUMIFS(Movimentações!$E$4:$E$5000,Movimentações!$C$4:$C$5000,A10,Movimentações!$D$4:$D$5000,"Entrada"),0) -> 50 | I10: =IFERROR(SUMIFS(Movimentações!$E$4:$E$5000,Movimentações!$C$4:$C$5000,A10,Movimentações!$D$4:$D$5000,"Saída"),0) -> 6 | J10: =IF(A10="","",E10+H10-I10) -> 44 | K10: =IF(A10="","",J10*F10) -> 123.2 | L10: =IF(A10="","",IF(J10<=0,"⚠ SEM ESTOQUE",IF(J10<D10,"⬇ ABAIXO DO MÍN.",IF(J10<D10*1.5,"➡ ATENÇÃO","✔ NORMAL")))) -> ✔ NORMAL | M10: =IF(I10=0,0,IFERROR(I10/MAX(1,SUMPRODUCT(MAX((Movimentações!$C$4:$C$5000=A10)*(Movimentações!$D$4:$D$5000="Saída")*Movimentações!$B$4:$B$5000))-SUMPRODUCT(MIN(IF((Movimentações!$C$4:$C$5000=A10)*(Movimentações!$D$4:$D$5000="Saída")=1,Movimentações!$B$4:$B$5000)))+1),0)) -> 0.00013007566 | N10: =IF(M10<=0,"-",IF(J10<=0,0,ROUND(J10/M10,0))) -> 338265 | O10: =ROUND(M10*G10+D10,0) -> 5 | P10: =IF(A10="","",IF(COUNTIF(Movimentações!$C$4:$C$5000,A10)=0,"Sem movim.",SUMPRODUCT(MAX((Movimentações!$C$4:$C$5000=A10)*Movimentações!$B$4:$B$5000)))) -> 46126 | Q10: =IF(OR(L10="✔ NORMAL",L10="",A10=""),999999,(J10-D10)+ROW()/100000) -> 999999 | R10: =IF(I10=0,-ROW()/100000,I10+(1-ROW()/100000)) -> 6.9999
A11: =IF('Cad. Materiais'!B11="","",'Cad. Materiais'!B11) -> Cola | B11: =IFERROR(VLOOKUP(A11,'Cad. Materiais'!$B$4:$D$53,3,FALSE),"") -> Escritório | C11: =IFERROR(VLOOKUP(A11,'Cad. Materiais'!$B$4:$C$53,2,FALSE),"") -> Tubo | D11: =IFERROR(VLOOKUP(A11,'Cad. Materiais'!$B$4:$E$53,4,FALSE),0) -> 2 | E11: =IFERROR(VLOOKUP(A11,'Cad. Materiais'!$B$4:$F$53,5,FALSE),0) -> 1 | F11: =IFERROR(VLOOKUP(A11,'Cad. Materiais'!$B$4:$G$53,6,FALSE),0) -> 3.5 | G11: =IFERROR(VLOOKUP(A11,'Cad. Materiais'!$B$4:$H$53,7,FALSE),0) -> 7 | H11: =IFERROR(SUMIFS(Movimentações!$E$4:$E$5000,Movimentações!$C$4:$C$5000,A11,Movimentações!$D$4:$D$5000,"Entrada"),0) -> 0 | I11: =IFERROR(SUMIFS(Movimentações!$E$4:$E$5000,Movimentações!$C$4:$C$5000,A11,Movimentações!$D$4:$D$5000,"Saída"),0) -> 0 | J11: =IF(A11="","",E11+H11-I11) -> 1 | K11: =IF(A11="","",J11*F11) -> 3.5 | L11: =IF(A11="","",IF(J11<=0,"⚠ SEM ESTOQUE",IF(J11<D11,"⬇ ABAIXO DO MÍN.",IF(J11<D11*1.5,"➡ ATENÇÃO","✔ NORMAL")))) -> ⬇ ABAIXO DO MÍN. | M11: =IF(I11=0,0,IFERROR(I11/MAX(1,SUMPRODUCT(MAX((Movimentações!$C$4:$C$5000=A11)*(Movimentações!$D$4:$D$5000="Saída")*Movimentações!$B$4:$B$5000))-SUMPRODUCT(MIN(IF((Movimentações!$C$4:$C$5000=A11)*(Movimentações!$D$4:$D$5000="Saída")=1,Movimentações!$B$4:$B$5000)))+1),0)) -> 0 | N11: =IF(M11<=0,"-",IF(J11<=0,0,ROUND(J11/M11,0))) -> - | O11: =ROUND(M11*G11+D11,0) -> 2 | P11: =IF(A11="","",IF(COUNTIF(Movimentações!$C$4:$C$5000,A11)=0,"Sem movim.",SUMPRODUCT(MAX((Movimentações!$C$4:$C$5000=A11)*Movimentações!$B$4:$B$5000)))) -> Sem movim. | Q11: =IF(OR(L11="✔ NORMAL",L11="",A11=""),999999,(J11-D11)+ROW()/100000) -> -0.99989 | R11: =IF(I11=0,-ROW()/100000,I11+(1-ROW()/100000)) -> -0.00011
A12: =IF('Cad. Materiais'!B12="","",'Cad. Materiais'!B12) -> Grampo normal | B12: =IFERROR(VLOOKUP(A12,'Cad. Materiais'!$B$4:$D$53,3,FALSE),"") -> Escritório | C12: =IFERROR(VLOOKUP(A12,'Cad. Materiais'!$B$4:$C$53,2,FALSE),"") -> Caixa | D12: =IFERROR(VLOOKUP(A12,'Cad. Materiais'!$B$4:$E$53,4,FALSE),0) -> 1 | E12: =IFERROR(VLOOKUP(A12,'Cad. Materiais'!$B$4:$F$53,5,FALSE),0) -> 2 | F12: =IFERROR(VLOOKUP(A12,'Cad. Materiais'!$B$4:$G$53,6,FALSE),0) -> 6 | G12: =IFERROR(VLOOKUP(A12,'Cad. Materiais'!$B$4:$H$53,7,FALSE),0) -> 7 | H12: =IFERROR(SUMIFS(Movimentações!$E$4:$E$5000,Movimentações!$C$4:$C$5000,A12,Movimentações!$D$4:$D$5000,"Entrada"),0) -> 0 | I12: =IFERROR(SUMIFS(Movimentações!$E$4:$E$5000,Movimentações!$C$4:$C$5000,A12,Movimentações!$D$4:$D$5000,"Saída"),0) -> 2 | J12: =IF(A12="","",E12+H12-I12) -> 0 | K12: =IF(A12="","",J12*F12) -> 0 | L12: =IF(A12="","",IF(J12<=0,"⚠ SEM ESTOQUE",IF(J12<D12,"⬇ ABAIXO DO MÍN.",IF(J12<D12*1.5,"➡ ATENÇÃO","✔ NORMAL")))) -> ⚠ SEM ESTOQUE | M12: =IF(I12=0,0,IFERROR(I12/MAX(1,SUMPRODUCT(MAX((Movimentações!$C$4:$C$5000=A12)*(Movimentações!$D$4:$D$5000="Saída")*Movimentações!$B$4:$B$5000))-SUMPRODUCT(MIN(IF((Movimentações!$C$4:$C$5000=A12)*(Movimentações!$D$4:$D$5000="Saída")=1,Movimentações!$B$4:$B$5000)))+1),0)) -> 4.3370777e-05 | N12: =IF(M12<=0,"-",IF(J12<=0,0,ROUND(J12/M12,0))) -> 0 | O12: =ROUND(M12*G12+D12,0) -> 1 | P12: =IF(A12="","",IF(COUNTIF(Movimentações!$C$4:$C$5000,A12)=0,"Sem movim.",SUMPRODUCT(MAX((Movimentações!$C$4:$C$5000=A12)*Movimentações!$B$4:$B$5000)))) -> 46113 | Q12: =IF(OR(L12="✔ NORMAL",L12="",A12=""),999999,(J12-D12)+ROW()/100000) -> -0.99988 | R12: =IF(I12=0,-ROW()/100000,I12+(1-ROW()/100000)) -> 2.99988
A13: =IF('Cad. Materiais'!B13="","",'Cad. Materiais'!B13) -> Grampo 23/10 | B13: =IFERROR(VLOOKUP(A13,'Cad. Materiais'!$B$4:$D$53,3,FALSE),"") -> Escritório | C13: =IFERROR(VLOOKUP(A13,'Cad. Materiais'!$B$4:$C$53,2,FALSE),"") -> Caixa | D13: =IFERROR(VLOOKUP(A13,'Cad. Materiais'!$B$4:$E$53,4,FALSE),0) -> 1 | E13: =IFERROR(VLOOKUP(A13,'Cad. Materiais'!$B$4:$F$53,5,FALSE),0) -> 2 | F13: =IFERROR(VLOOKUP(A13,'Cad. Materiais'!$B$4:$G$53,6,FALSE),0) -> 9.5 | G13: =IFERROR(VLOOKUP(A13,'Cad. Materiais'!$B$4:$H$53,7,FALSE),0) -> 7 | H13: =IFERROR(SUMIFS(Movimentações!$E$4:$E$5000,Movimentações!$C$4:$C$5000,A13,Movimentações!$D$4:$D$5000,"Entrada"),0) -> 0 | I13: =IFERROR(SUMIFS(Movimentações!$E$4:$E$5000,Movimentações!$C$4:$C$5000,A13,Movimentações!$D$4:$D$5000,"Saída"),0) -> 0 | J13: =IF(A13="","",E13+H13-I13) -> 2 | K13: =IF(A13="","",J13*F13) -> 19 | L13: =IF(A13="","",IF(J13<=0,"⚠ SEM ESTOQUE",IF(J13<D13,"⬇ ABAIXO DO MÍN.",IF(J13<D13*1.5,"➡ ATENÇÃO","✔ NORMAL")))) -> ✔ NORMAL | M13: =IF(I13=0,0,IFERROR(I13/MAX(1,SUMPRODUCT(MAX((Movimentações!$C$4:$C$5000=A13)*(Movimentações!$D$4:$D$5000="Saída")*Movimentações!$B$4:$B$5000))-SUMPRODUCT(MIN(IF((Movimentações!$C$4:$C$5000=A13)*(Movimentações!$D$4:$D$5000="Saída")=1,Movimentações!$B$4:$B$5000)))+1),0)) -> 0 | N13: =IF(M13<=0,"-",IF(J13<=0,0,ROUND(J13/M13,0))) -> - | O13: =ROUND(M13*G13+D13,0) -> 1 | P13: =IF(A13="","",IF(COUNTIF(Movimentações!$C$4:$C$5000,A13)=0,"Sem movim.",SUMPRODUCT(MAX((Movimentações!$C$4:$C$5000=A13)*Movimentações!$B$4:$B$5000)))) -> Sem movim. | Q13: =IF(OR(L13="✔ NORMAL",L13="",A13=""),999999,(J13-D13)+ROW()/100000) -> 999999 | R13: =IF(I13=0,-ROW()/100000,I13+(1-ROW()/100000)) -> -0.00013
A14: =IF('Cad. Materiais'!B14="","",'Cad. Materiais'!B14) -> Elástico | B14: =IFERROR(VLOOKUP(A14,'Cad. Materiais'!$B$4:$D$53,3,FALSE),"") -> Escritório | C14: =IFERROR(VLOOKUP(A14,'Cad. Materiais'!$B$4:$C$53,2,FALSE),"") -> Pacote | D14: =IFERROR(VLOOKUP(A14,'Cad. Materiais'!$B$4:$E$53,4,FALSE),0) -> 2 | E14: =IFERROR(VLOOKUP(A14,'Cad. Materiais'!$B$4:$F$53,5,FALSE),0) -> 12 | F14: =IFERROR(VLOOKUP(A14,'Cad. Materiais'!$B$4:$G$53,6,FALSE),0) -> 5.2 | G14: =IFERROR(VLOOKUP(A14,'Cad. Materiais'!$B$4:$H$53,7,FALSE),0) -> 10 | H14: =IFERROR(SUMIFS(Movimentações!$E$4:$E$5000,Movimentações!$C$4:$C$5000,A14,Movimentações!$D$4:$D$5000,"Entrada"),0) -> 0 | I14: =IFERROR(SUMIFS(Movimentações!$E$4:$E$5000,Movimentações!$C$4:$C$5000,A14,Movimentações!$D$4:$D$5000,"Saída"),0) -> 3 | J14: =IF(A14="","",E14+H14-I14) -> 9 | K14: =IF(A14="","",J14*F14) -> 46.8 | L14: =IF(A14="","",IF(J14<=0,"⚠ SEM ESTOQUE",IF(J14<D14,"⬇ ABAIXO DO MÍN.",IF(J14<D14*1.5,"➡ ATENÇÃO","✔ NORMAL")))) -> ✔ NORMAL | M14: =IF(I14=0,0,IFERROR(I14/MAX(1,SUMPRODUCT(MAX((Movimentações!$C$4:$C$5000=A14)*(Movimentações!$D$4:$D$5000="Saída")*Movimentações!$B$4:$B$5000))-SUMPRODUCT(MIN(IF((Movimentações!$C$4:$C$5000=A14)*(Movimentações!$D$4:$D$5000="Saída")=1,Movimentações!$B$4:$B$5000)))+1),0)) -> 6.5097103e-05 | N14: =IF(M14<=0,"-",IF(J14<=0,0,ROUND(J14/M14,0))) -> 138255 | O14: =ROUND(M14*G14+D14,0) -> 2 | P14: =IF(A14="","",IF(COUNTIF(Movimentações!$C$4:$C$5000,A14)=0,"Sem movim.",SUMPRODUCT(MAX((Movimentações!$C$4:$C$5000=A14)*Movimentações!$B$4:$B$5000)))) -> 46084 | Q14: =IF(OR(L14="✔ NORMAL",L14="",A14=""),999999,(J14-D14)+ROW()/100000) -> 999999 | R14: =IF(I14=0,-ROW()/100000,I14+(1-ROW()/100000)) -> 3.99986
A15: =IF('Cad. Materiais'!B15="","",'Cad. Materiais'!B15) -> Durex grande | B15: =IFERROR(VLOOKUP(A15,'Cad. Materiais'!$B$4:$D$53,3,FALSE),"") -> Escritório | C15: =IFERROR(VLOOKUP(A15,'Cad. Materiais'!$B$4:$C$53,2,FALSE),"") -> Unidade | D15: =IFERROR(VLOOKUP(A15,'Cad. Materiais'!$B$4:$E$53,4,FALSE),0) -> 2 | E15: =IFERROR(VLOOKUP(A15,'Cad. Materiais'!$B$4:$F$53,5,FALSE),0) -> 0 | F15: =IFERROR(VLOOKUP(A15,'Cad. Materiais'!$B$4:$G$53,6,FALSE),0) -> 8.9 | G15: =IFERROR(VLOOKUP(A15,'Cad. Materiais'!$B$4:$H$53,7,FALSE),0) -> 7 | H15: =IFERROR(SUMIFS(Movimentações!$E$4:$E$5000,Movimentações!$C$4:$C$5000,A15,Movimentações!$D$4:$D$5000,"Entrada"),0) -> 0 | I15: =IFERROR(SUMIFS(Movimentações!$E$4:$E$5000,Movimentações!$C$4:$C$5000,A15,Movimentações!$D$4:$D$5000,"Saída"),0) -> 0 | J15: =IF(A15="","",E15+H15-I15) -> 0 | K15: =IF(A15="","",J15*F15) -> 0 | L15: =IF(A15="","",IF(J15<=0,"⚠ SEM ESTOQUE",IF(J15<D15,"⬇ ABAIXO DO MÍN.",IF(J15<D15*1.5,"➡ ATENÇÃO","✔ NORMAL")))) -> ⚠ SEM ESTOQUE | M15: =IF(I15=0,0,IFERROR(I15/MAX(1,SUMPRODUCT(MAX((Movimentações!$C$4:$C$5000=A15)*(Movimentações!$D$4:$D$5000="Saída")*Movimentações!$B$4:$B$5000))-SUMPRODUCT(MIN(IF((Movimentações!$C$4:$C$5000=A15)*(Movimentações!$D$4:$D$5000="Saída")=1,Movimentações!$B$4:$B$5000)))+1),0)) -> 0 | N15: =IF(M15<=0,"-",IF(J15<=0,0,ROUND(J15/M15,0))) -> - | O15: =ROUND(M15*G15+D15,0) -> 2 | P15: =IF(A15="","",IF(COUNTIF(Movimentações!$C$4:$C$5000,A15)=0,"Sem movim.",SUMPRODUCT(MAX((Movimentações!$C$4:$C$5000=A15)*Movimentações!$B$4:$B$5000)))) -> Sem movim. | Q15: =IF(OR(L15="✔ NORMAL",L15="",A15=""),999999,(J15-D15)+ROW()/100000) -> -1.99985 | R15: =IF(I15=0,-ROW()/100000,I15+(1-ROW()/100000)) -> -0.00015
... A53: =IF('Cad. Materiais'!B53="","",'Cad. Materiais'!B53) | B53: =IFERROR(VLOOKUP(A53,'Cad. Materiais'!$B$4:$D$53,3,FALSE),"") | C53: =IFERROR(VLOOKUP(A53,'Cad. Materiais'!$B$4:$C$53,2,FALSE),"") | D53: =IFERROR(VLOOKUP(A53,'Cad. Materiais'!$B$4:$E$53,4,FALSE),0) -> 0 | E53: =IFERROR(VLOOKUP(A53,'Cad. Materiais'!$B$4:$F$53,5,FALSE),0) -> 0 | F53: =IFERROR(VLOOKUP(A53,'Cad. Materiais'!$B$4:$G$53,6,FALSE),0) -> 0 | G53: =IFERROR(VLOOKUP(A53,'Cad. Materiais'!$B$4:$H$53,7,FALSE),0) -> 0 | H53: =IFERROR(SUMIFS(Movimentações!$E$4:$E$5000,Movimentações!$C$4:$C$5000,A53,Movimentações!$D$4:$D$5000,"Entrada"),0) -> 0 | I53: =IFERROR(SUMIFS(Movimentações!$E$4:$E$5000,Movimentações!$C$4:$C$5000,A53,Movimentações!$D$4:$D$5000,"Saída"),0) -> 0 | J53: =IF(A53="","",E53+H53-I53) | K53: =IF(A53="","",J53*F53) | L53: =IF(A53="","",IF(J53<=0,"⚠ SEM ESTOQUE",IF(J53<D53,"⬇ ABAIXO DO MÍN.",IF(J53<D53*1.5,"➡ ATENÇÃO","✔ NORMAL")))) | M53: =IF(I53=0,0,IFERROR(I53/MAX(1,SUMPRODUCT(MAX((Movimentações!$C$4:$C$5000=A53)*(Movimentações!$D$4:$D$5000="Saída")*Movimentações!$B$4:$B$5000))-SUMPRODUCT(MIN(IF((Movimentações!$C$4:$C$5000=A53)*(Movimentações!$D$4:$D$5000="Saída")=1,Movimentações!$B$4:$B$5000)))+1),0)) -> 0 | N53: =IF(M53<=0,"-",IF(J53<=0,0,ROUND(J53/M53,0))) -> - | O53: =ROUND(M53*G53+D53,0) -> 0 | P53: =IF(A53="","",IF(COUNTIF(Movimentações!$C$4:$C$5000,A53)=0,"Sem movim.",SUMPRODUCT(MAX((Movimentações!$C$4:$C$5000=A53)*Movimentações!$B$4:$B$5000)))) | Q53: =IF(OR(L53="✔ NORMAL",L53="",A53=""),999999,(J53-D53)+ROW()/100000) -> 999999 | R53: =IF(I53=0,-ROW()/100000,I53+(1-ROW()/100000)) -> -0.00053
A54: TOTAL | H54: =SUM(H4:H53) -> 322 | I54: =SUM(I4:I53) -> 290 | J54: =SUM(J4:J53) -> 588 | K54: =SUM(K4:K53) -> 1039.7

Sheet Movimentações
A1: 📝 MOVIMENTAÇÕES — 2026
A2: ℹ️ Use as listas suspensas (Material, Tipo, Colaborador, Departamento). Quantidade deve ser maior que zero.
A3: ID | B3: Data | C3: Material | D3: Tipo | E3: Quantidade | F3: Colaborador | G3: Departamento | H3: Observação | I3: Registrado por
A4: 1 | B4: 46025 | C4: Resma de papel A4 | D4: Saída | E4: 1 | F4: Larissa Mendes | G4: Administrativo | I4: Laura Ribeiro
A5: 2 | B5: 46025 | C5: Clips | D5: Saída | E5: 1 | F5: Ariane Costa | G5: Administrativo | I5: Laura Ribeiro
A6: 3 | B6: 46025 | C6: Caneta Azul | D6: Saída | E6: 1 | F6: Ariane Costa | G6: Administrativo | I6: Laura Ribeiro
A7: 4 | B7: 46025 | C7: Resma de papel A4 | D7: Saída | E7: 2 | F7: Ariane Costa | G7: Administrativo | I7: Laura Ribeiro
A8: 5 | B8: 46026 | C8: Resma de papel A4 | D8: Saída | E8: 3 | F8: Camila Rocha | G8: Administrativo | I8: Laura Ribeiro
A9: 6 | B9: 46026 | C9: Caneta Azul | D9: Saída | E9: 1 | F9: Érica Felipe | G9: Administrativo | I9: Laura Ribeiro
A10: 7 | B10: 46026 | C10: Resma de papel A4 | D10: Saída | E10: 1 | F10: Érica Felipe | G10: Administrativo | I10: Laura Ribeiro
A11: 8 | B11: 46027 | C11: Envelope Janelado | D11: Saída | E11: 1 | F11: Pedro Cardoso | G11: Administrativo | I11: Laura Ribeiro
A12: 9 | B12: 46027 | C12: Elástico | D12: Saída | E12: 1 | F12: Laura Ribeiro | G12: Administrativo | I12: Laura Ribeiro
A13: 10 | B13: 46027 | C13: Resma de papel A4 | D13: Saída | E13: 1 | F13: Laura Ribeiro | G13: Administrativo | I13: Laura Ribeiro
A14: 11 | B14: 46027 | C14: Resma de papel A4 | D14: Saída | E14: 1 | F14: Matheus Alves | G14: Administrativo | I14: Laura Ribeiro
A15: 12 | B15: 46027 | C15: Caneta Azul | D15: Saída | E15: 1 | F15: Liliana Santos | G15: Administrativo | I15: Laura Ribeiro
... A17: 14 | B17: 46027 | C17: Envelope Pardo | D17: Saída | E17: 1 | F17: Ronaldo Martins | G17: Administrativo | I17: Laura Ribeiro
A18: 15 | B18: 46032 | C18: Envelope Janelado | D18: Saída | E18: 50 | F18: Beatriz Lima | G18: Administrativo | H18: 25% da caixa | I18: Laura Ribeiro
A19: 16 | B19: 46032 | C19: Resma de papel A4 | D19: Saída | E19: 2 | F19: Beatriz Lima | G19: Administrativo | I19: Laura Ribeiro
A20: 17 | B20: 46032 | C20: Resma de papel A4 | D20: Entrada | E20: 16 | F20: Laura Ribeiro | G20: Compras | H20: Reposição mensal | I20: Laura Ribeiro
A21: 18 | B21: 46054 | C21: Envelope Pardo | D21: Saída | E21: 1 | F21: Lucas Pereira | G21: Operacional | I21: Laura Ribeiro
A22: 19 | B22: 46054 | C22: Envelope Pardo | D22: Saída | E22: 1 | F22: Beatriz Lima | G22: Administrativo | I22: Laura Ribeiro
A23: 20 | B23: 46055 | C23: Resma de papel A4 | D23: Saída | E23: 1 | F23: Beatriz Lima | G23: Administrativo | I23: Laura Ribeiro
A24: 21 | B24: 46055 | C24: Resma de papel A4 | D24: Saída | E24: 1 | F24: Beatriz Lima | G24: Administrativo | I24: Laura Ribeiro
A25: 22 | B25: 46056 | C25: Envelope Pardo | D25: Saída | E25: 2 | F25: Érica Felipe | G25: Administrativo | I25: Laura Ribeiro
A26: 23 | B26: 46056 | C26: Envelope Pardo | D26: Entrada | E26: 100 | F26: Laura Ribeiro | G26: Compras | H26: Reposição | I26: Laura Ribeiro
A27: 24 | B27: 46057 | C27: Grampeador | D27: Entrada | E27: 3 | F27: Laura Ribeiro | G27: Compras | H27: Novo lote | I27: Laura Ribeiro
A28: 25 | B28: 46057 | C28: Resma de papel A4 | D28: Entrada | E28: 10 | F28: Laura Ribeiro | G28: Compras | H28: Reposição | I28: Laura Ribeiro
A29: 26 | B29: 46057 | C29: Envelope Pardo | D29: Entrada | E29: 100 | F29: Laura Ribeiro | G29: Compras | H29: Reposição | I29: Laura Ribeiro
A30: 27 | B30: 46064 | C30: Envelope Pardo | D30: Saída | E30: 1 | F30: Laura Ribeiro | G30: Administrativo | I30: Laura Ribeiro
A31: 28 | B31: 46064 | C31: Resma de papel A4 | D31: Saída | E31: 1 | F31: Laura Ribeiro | G31: Administrativo | I31: Laura Ribeiro
A32: 29 | B32: 46064 | C32: Resma de papel A4 | D32: Saída | E32: 1 | F32: Ronaldo Martins | G32: Administrativo | I32: Laura Ribeiro
A33: 30 | B33: 46067 | C33: Resma de papel A4 | D33: Saída | E33: 1 | F33: Ariane Costa | G33: Administrativo | I33: Laura Ribeiro
A34: 31 | B34: 46067 | C34: Resma de papel A4 | D34: Saída | E34: 1 | F34: Ronaldo Martins | G34: Administrativo | I34: Laura Ribeiro
A35: 32 | B35: 46068 | C35: Envelope Janelado | D35: Saída | E35: 44 | F35: Larissa Mendes | G35: Administrativo | I35: Laura Ribeiro
A36: 33 | B36: 46070 | C36: Envelope Janelado | D36: Saída | E36: 36 | F36: Ariane Costa | G36: Administrativo | I36: Laura Ribeiro
A37: 34 | B37: 46071 | C37: Envelope Pardo | D37: Saída | E37: 1 | F37: Beatriz Lima | G37: Administrativo | I37: Laura Ribeiro
A38: 35 | B38: 46072 | C38: Resma de papel A4 | D38: Saída | E38: 1 | F38: André Souza | G38: Administrativo | I38: Laura Ribeiro
A39: 36 | B39: 46082 | C39: Resma de papel A4 | D39: Saída | E39: 1 | F39: Matheus Alves | G39: Administrativo | I39: Laura Ribeiro
A40: 37 | B40: 46082 | C40: Envelope Janelado | D40: Saída | E40: 1 | F40: Érica Felipe | G40: Administrativo | I40: Laura Ribeiro
A41: 38 | B41: 46082 | C41: Bloco de notas | D41: Entrada | E41: 15 | F41: Laura Ribeiro | G41: Compras | H41: Novo lote | I41: Laura Ribeiro
...

Sheet Cad. Materiais
A1: 🗂️ CADASTRO DE MATERIAIS
A2: ℹ️ Para adicionar material: preencha uma nova linha. Para desativar: mude 'Ativo?' para 'Não'.
A3: ID | B3: Material | C3: Unidade | D3: Categoria | E3: Estoque Mínimo | F3: Estoque Inicial Jan | G3: Custo Unit. (R$) | H3: Lead Time (dias) | I3: Fornecedor | J3: 0
A4: 1 | B4: Resma de papel A4 | C4: Unidade | D4: Papel/Impressão | E4: 5 | F4: 16 | G4: 28.5 | H4: 7 | I4: Papelaria Central | J4: =IF(B4="","",MAX($J$3:J3)+1) -> 1
A5: 2 | B5: Envelope Pardo | C5: Unidade | D5: Envelopes | E5: 10 | F5: 5 | G5: 0.8 | H5: 5 | I5: Distribuidora Office | J5: =IF(B5="","",MAX($J$3:J4)+1) -> 2
A6: 3 | B6: Clips | C6: Caixa | D6: Escritório | E6: 2 | F6: 4 | G6: 8.9 | H6: 5 | I6: Papelaria Central | J6: =IF(B6="","",MAX($J$3:J5)+1) -> 3
A7: 4 | B7: Envelope Janelado | C7: Unidade | D7: Envelopes | E7: 50 | F7: 500 | G7: 0.45 | H7: 10 | I7: Distribuidora Office | J7: =IF(B7="","",MAX($J$3:J6)+1) -> 4
A8: 5 | B8: Post-IT | C8: Unidade | D8: Escritório | E8: 2 | F8: 0 | G8: 12.5 | H8: 7 | I8: Papelaria Central | J8: =IF(B8="","",MAX($J$3:J7)+1) -> 5
A9: 6 | B9: Marcador de texto | C9: Unidade | D9: Escritório | E9: 2 | F9: 0 | G9: 4.2 | H9: 7 | I9: Papelaria Central | J9: =IF(B9="","",MAX($J$3:J8)+1) -> 6
A10: 7 | B10: Caneta Azul | C10: Unidade | D10: Escritório | E10: 5 | F10: 0 | G10: 2.8 | H10: 3 | I10: Papelaria Central | J10: =IF(B10="","",MAX($J$3:J9)+1) -> 7
A11: 8 | B11: Cola | C11: Tubo | D11: Escritório | E11: 2 | F11: 1 | G11: 3.5 | H11: 7 | I11: Papelaria Central | J11: =IF(B11="","",MAX($J$3:J10)+1) -> 8
A12: 9 | B12: Grampo normal | C12: Caixa | D12: Escritório | E12: 1 | F12: 2 | G12: 6 | H12: 7 | I12: Papelaria Central | J12: =IF(B12="","",MAX($J$3:J11)+1) -> 9
A13: 10 | B13: Grampo 23/10 | C13: Caixa | D13: Escritório | E13: 1 | F13: 2 | G13: 9.5 | H13: 7 | I13: Papelaria Central | J13: =IF(B13="","",MAX($J$3:J12)+1) -> 10
A14: 11 | B14: Elástico | C14: Pacote | D14: Escritório | E14: 2 | F14: 12 | G14: 5.2 | H14: 10 | I14: Papelaria Central | J14: =IF(B14="","",MAX($J$3:J13)+1) -> 11
A15: 12 | B15: Durex grande | C15: Unidade | D15: Escritório | E15: 2 | F15: 0 | G15: 8.9 | H15: 7 | I15: Papelaria Central | J15: =IF(B15="","",MAX($J$3:J14)+1) -> 12
... A28: 25 | B28: Papel A3 | C28: Resma | D28: Papel/Impressão | E28: 2 | F28: 0 | G28: 45 | H28: 10 | I28: Papelaria Central | J28: =IF(B28="","",MAX($J$3:J27)+1) -> 25
J29: =IF(B29="","",MAX($J$3:J28)+1)
J30: =IF(B30="","",MAX($J$3:J29)+1)
J31: =IF(B31="","",MAX($J$3:J30)+1)
J32: =IF(B32="","",MAX($J$3:J31)+1)
J33: =IF(B33="","",MAX($J$3:J32)+1)
J34: =IF(B34="","",MAX($J$3:J33)+1)
J35: =IF(B35="","",MAX($J$3:J34)+1)
J36: =IF(B36="","",MAX($J$3:J35)+1)
J37: =IF(B37="","",MAX($J$3:J36)+1)
J38: =IF(B38="","",MAX($J$3:J37)+1)
J39: =IF(B39="","",MAX($J$3:J38)+1)
J40: =IF(B40="","",MAX($J$3:J39)+1)
... J53: =IF(B53="","",MAX($J$3:J52)+1)

Sheet Cad. Colaboradores
A1: 👥 CADASTRO DE COLABORADORES
A2: ℹ️ Para adicionar: preencha uma nova linha. Para desativar: mude 'Ativo?' para 'Não' (preserva o histórico).
A3: ID | B3: Nome | C3: Departamento | D3: E-mail | E3: Telefone | F3: Ativo? | G3: 0
